Workbook

Sheet Calculo Informes
B1: Periodo Informe Mensual
B2: Fecha Inicio Periodo | C2: 46091
B3: Fecha Termino Periodo | C3: 46121
B5: Grupo | C5: INC | D5: Warning | E5: REQ | F5: Total por Equipo
B6: Middleware | C6: =SUM(COUNTIFS(OscarMora!$B$2:$B$10001,">="&C2,OscarMora!$B$2:$B$10001,"<="&C3,OscarMora!$F$2:$F$10001,"=INC"), COUNTIFS(AmericoSaravia!$B$2:$B$10072,">="&C2,AmericoSaravia!$B$2:$B$10072,"<="&C3,AmericoSaravia!$F$2:$F$10072,"=INC"), COUNTIFS(GabrielNuñez!$B$2:$B$9983,">="&C2,GabrielNuñez!$B$2:$B$9983,"<="&C3,GabrielNuñez!$F$2:$F$9983,"=INC")) -> 0 | D6: =SUM(COUNTIFS(OscarMora!$B$2:$B$10001,">="&C2,OscarMora!$B$2:$B$10001,"<="&C3,OscarMora!$F$2:$F$10001,"=WARNING"),COUNTIFS(AmericoSaravia!$B$2:$B$10072,">="&C2,AmericoSaravia!$B$2:$B$10072,"<="&C3,AmericoSaravia!$F$2:$F$10072,"=WARNING"),COUNTIFS(GabrielNuñez!$B$2:$B$9983,">="&C2,GabrielNuñez!$B$2:$B$9983,"<="&C3,GabrielNuñez!$F$2:$F$9983,"=WARNING")) -> 3 | E6: =SUM(COUNTIFS(OscarMora!$B$2:$B$10001,">="&C2,OscarMora!$B$2:$B$10001,"<="&C3,OscarMora!$F$2:$F$10001,"=REQ"),COUNTIFS(AmericoSaravia!$B$2:$B$10072,">="&C2,AmericoSaravia!$B$2:$B$10072,"<="&C3,AmericoSaravia!$F$2:$F$10072,"=REQ"),COUNTIFS(GabrielNuñez!$B$2:$B$9983,">="&C2,GabrielNuñez!$B$2:$B$9983,"<="&C3,GabrielNuñez!$F$2:$F$9983,"=REQ")) -> 215 | F6: =SUM(C6:E6) -> 218
B7: Administración Nube | C7: =SUM(COUNTIFS(GonzaloRodriguez!$B$2:$B$9988,">="&C2,GonzaloRodriguez!$B$2:$B$9988,"<="&C3,GonzaloRodriguez!$F$2:$F$9988,"=INC"),COUNTIFS(CesarGonzalez!$B$2:$B$10000,">="&C2,CesarGonzalez!$B$2:$B$10000,"<="&C3,CesarGonzalez!$F$2:$F$10000,"=INC")) -> 0 | D7: =SUM(COUNTIFS(GonzaloRodriguez!$B$2:$B$9988,">="&C2,GonzaloRodriguez!$B$2:$B$9988,"<="&C3,GonzaloRodriguez!$F$2:$F$9988,"=WARNING"),COUNTIFS(CesarGonzalez!$B$2:$B$10000,">="&C2,CesarGonzalez!$B$2:$B$10000,"<="&C3,CesarGonzalez!$F$2:$F$10000,"=WARNING")) -> 0 | E7: =SUM(COUNTIFS(GonzaloRodriguez!$B$2:$B$9988,">="&C2,GonzaloRodriguez!$B$2:$B$9988,"<="&C3,GonzaloRodriguez!$F$2:$F$9988,"=REQ"),COUNTIFS(CesarGonzalez!$B$2:$B$10000,">="&C2,CesarGonzalez!$B$2:$B$10000,"<="&C3,CesarGonzalez!$F$2:$F$10000,"=REQ")) -> 61 | F7: =SUM(C7:E7) -> 61
B8: Administración SO, Servidores y Dominios | C8: =SUM(COUNTIFS(RodrigoLorca!$B$2:$B$10000,">="&C2,RodrigoLorca!$B$2:$B$10000,"<="&C3,RodrigoLorca!$F$2:$F$10000,"=INC"),COUNTIFS(PabloSalazar!$B$2:$B$10000,">="&C2,PabloSalazar!$B$2:$B$10000,"<="&C3,PabloSalazar!$F$2:$F$10000,"=INC")) -> 0 | D8: =SUM(COUNTIFS(RodrigoLorca!$B$2:$B$10000,">="&C2,RodrigoLorca!$B$2:$B$10000,"<="&C3,RodrigoLorca!$F$2:$F$10000,"=WARNING"),COUNTIFS(PabloSalazar!$B$2:$B$10000,">="&C2,PabloSalazar!$B$2:$B$10000,"<="&C3,PabloSalazar!$F$2:$F$10000,"=WARNING")) -> 8 | E8: =SUM(COUNTIFS(RodrigoLorca!$B$2:$B$10000,">="&C2,RodrigoLorca!$B$2:$B$10000,"<="&C3,RodrigoLorca!$F$2:$F$10000,"=REQ"),COUNTIFS(PabloSalazar!$B$2:$B$10000,">="&C2,PabloSalazar!$B$2:$B$10000,"<="&C3,PabloSalazar!$F$2:$F$10000,"=REQ")) -> 44 | F8: =SUM(C8:E8) -> 52
B9: Monitoreo y Respaldo | C9: =SUM(COUNTIFS(CarlosJara!$B$2:$B$10006,">="&C2,CarlosJara!$B$2:$B$10006,"<="&C3,CarlosJara!$F$2:$F$10006,"=INC"),COUNTIFS(JPBuzeta!$B$2:$B$10010,">="&C2,JPBuzeta!$B$2:$B$10010,"<="&C3,JPBuzeta!$F$2:$F$10010,"=INC"),COUNTIFS(CristiánVásquez!$B$2:$B$9992,">="&C2,CristiánVásquez!$B$2:$B$9992,"<="&C3,CristiánVásquez!$F$2:$F$9992,"=INC"),COUNTIFS(AlejandroIpinza!$B$2:$B$10000,">="&C2,AlejandroIpinza!$B$2:$B$10000,"<="&C3,AlejandroIpinza!$F$2:$F$10000,"=INC")) -> 1 | D9: =SUM(COUNTIFS(CarlosJara!$B$2:$B$10006,">="&C2,CarlosJara!$B$2:$B$10006,"<="&C3,CarlosJara!$F$2:$F$10006,"=WARNING"),COUNTIFS(JPBuzeta!$B$2:$B$10010,">="&C2,JPBuzeta!$B$2:$B$10010,"<="&C3,JPBuzeta!$F$2:$F$10010,"=WARNING"),COUNTIFS(CristiánVásquez!$B$2:$B$9992,">="&C2,CristiánVásquez!$B$2:$B$9992,"<="&C3,CristiánVásquez!$F$2:$F$9992,"=WARNING"), COUNTIFS(AlejandroIpinza!$B$2:$B$10000,">="&C2,AlejandroIpinza!$B$2:$B$10000,"<="&C3,AlejandroIpinza!$F$2:$F$10000,"=WARNING")) -> 14 | E9: =SUM(COUNTIFS(CarlosJara!$B$2:$B$10006,">="&C2,CarlosJara!$B$2:$B$10006,"<="&C3,CarlosJara!$F$2:$F$10006,"=REQ"),COUNTIFS(JPBuzeta!$B$2:$B$10010,">="&C2,JPBuzeta!$B$2:$B$10010,"<="&C3,JPBuzeta!$F$2:$F$10010,"=REQ"),COUNTIFS(CristiánVásquez!$B$2:$B$9992,">="&C2,CristiánVásquez!$B$2:$B$9992,"<="&C3,CristiánVásquez!$F$2:$F$9992,"=REQ"),COUNTIFS(AlejandroIpinza!$B$2:$B$10000,">="&C2,AlejandroIpinza!$B$2:$B$10000,"<="&C3,AlejandroIpinza!$F$2:$F$10000,"=REQ")) -> 224 | F9: =SUM(C9:E9) -> 239
B11: Total Incidentes | C11: =SUM(C6:C9) -> 1
B12: Total Warning | C12: =SUM(D6:D9) -> 25
B13: Total Requerimientos | C13: =SUM(E6:E9) -> 544
B14: Total General | C14: =SUM(C11:C13) -> 570

Sheet CesarGonzalez
B1: FECHA SOLICITUD | C1: Periodo | D1: AREA / PERSONAL SOLICITANTE | E1: PROFESIONAL | F1: INC / REQ / WARNING | G1: Actividad | H1: Detalle / Observación | I1: Estado (en proceso, pendiente, finalizado) | J1: Tiempo estimado actividad
B2: 45737 | C2: 45723 | D2: Chileatiende | E2: Cesar Gonzalez | F2: REQ | G2: Ticket N° 14347 - URGENTE!!! Solicitud de actualización minisitio ipsenlinea :: Bajada servicio SIAGF en SUSESO | H2: Actualizar el minisitio de ipsenlinea (https://www.ipsenlinea.cl/) producto de la bajada del servicio SIAGF por parte de SUSESO, lo cual afecta al trámite reconocimiento de carga familiar y maternal.
B3: 45741 | C3: 45724 | D3: Chileatiende | E3: Cesar Gonzalez | F3: REQ | G3: Rollback de actualización minisitio ipsenlinea :: Bajada servicio SIAGF en SUSESO | H3: Se realiza rollback de actualizacion de minisitio requerido por Chileatiende durante las fechas 21/03 al 24/03 - Este cambio se realiza fuera de horario debido a que el sitio debia estar disponbile a primera hora del dia Martes 25/03
B4: 45741 | C4: 45725 | D4: Operaciones IPS | E4: Cesar Gonzalez | F4: REQ | G4: Seguimiento: [IPS] Temas Pendientes - Cloud Services ☁ | H4: Call a realizar todos los dias Martes a partir de las 9:30 Hrs - Se revisan temas pendientes y proyectos en curso correspondientes a Cloud Services IPS.
B5: 45742 | C5: 45726 | D5: Daniel Zamora Operaciones IPS | E5: Cesar Gonzalez | F5: REQ | G5: Ticket N° 14380 - Apagado Nodos 5-6 Proyecto AFPER | H5: Se realiza apagado de instancias AFPER-Consulta 5-6 correspondientes al proyecto AFPER solicitados por Daniel Zamora, realizada el drenaje respectivo en los balanceadores pertinentes.
B6: 45742 | C6: 45727 | D6: Operaciones IPS | E6: Cesar Gonzalez | F6: REQ | G6: Continuacion Seguimiento: [IPS] Temas Pendientes - Cloud Services ☁ | H6: Se continua call en donde se revisan temas pendientes y proyectos en curso correspondientes a Cloud Services IPS.
B7: 45743 | C7: 45728 | D7: Miguel Garrido - Abenis | E7: Cesar Gonzalez | F7: REQ | G7: Coordinación ABENIS - IPS | H7: Call de coordinacion
B8: 45743 | C8: 45729 | D8: Victor Bustos - IPS | E8: Cesar Gonzalez | F8: REQ | G8: Ticket N° 14393 - Encendido Instancias DEV AFPER | H8: Solicitan el encendido de instancias AFPER DEV en horario habil.
B9: 45743 | C9: 45730 | D9: Daniel Zamora Operaciones IPS | E9: Cesar Gonzalez | F9: REQ | G9: Call Presentacion De Estrategia Abenis | H9: Call de presentacion de estrategia y planificacion Abenis-IPS
B10: 45744 | C10: 45731 | D10: IPS-TIVIT | E10: Cesar Gonzalez | F10: REQ | G10: Call Seguimiento De Contrato MS Azure | H10: Call con TAM TIVIT y Daniel Zamora IPS para la estrategia de implementacion y configuracion del servicio PaaS Azure DevOps.
B11: 45744 | C11: 45732 | D11: Area SAP IPS - Area Operaciones IPS | E11: Cesar Gonzalez | F11: REQ | G11: Actividad Planificada - Fuera De Horario: Upgrade de S.O RHEL 8.10 en SAP HANA DB (10.88.1.135) 🗄️🗃️ | H11: Actividad planificada - fuera de horario con areas de SAP y Operaciones IPS, correspondiente al Upgrade de S.O para ambiente SAP HANA BD (10.88.1.135)
B12: 45747 | C12: 45733 | D12: Ricardo Orellana DBA IPS | E12: Cesar Gonzalez | F12: REQ | G12: Apoyo - Autorización del acceso de base de datos a SQL Database, Instancia administrada de SQL | H12: Se realizan las validaciones y verificacion de los usuarios dbamanager ya que actualmente Ricardo Orellana no tiene acceso a BD PaaS PROD con usuario administrador.
B13: 45748 | C13: 45748 | D13: Daniel Zamora Operaciones IPS | E13: Cesar Gonzalez | F13: REQ | G13: Continuacion Call Presentacion De Estrategia Abenis | H13: Usuario Christian Fuentes - Area DyM IPS requiere archivo de configuracion aplication.properties para el servicio App Services Garantia Estatal.
B14: 45748 | D14: Christian Fuentes IPS | E14: Cesar Gonzalez | F14: REQ | G14: Ticket N° 14459 - Solicitud Archivo De Configuracion App Services Garantia Estatal | H14: Usuario Angel Alvarez de Area Ciberseguridad IPS requiere lso certificados renovados wildcard para los dominios inp.cl e ips.gob.cl ya que estan proximos a expirar (11/04/25) Seran enviados y adjuntos en ticket creado.
B15: 45748 | D15: Angel Alvarez IPS | E15: Cesar Gonzalez | F15: REQ | G15: Ticket N° 14462 - Solicitud certificados wildcard inp.cl e ips.gob.cl | H15: Usuario: Gonzalo Sepulvedad solicita deshabilitar Scheduler de Apagado correspondiente al ambiente UAT PDP con fecha 02/04 hasta 04/04 volviendo nuevamente habilitar el Scheduler.
B16: 45749 | D16: Gonzalo Sepulveda IPS | E16: Cesar Gonzalez | F16: REQ | G16: Ticket N° 14479 - Deshabilitar Scheduler Apagado Ambientes UAT PDP | H16: Se coordina call con TAM Jorge Quiroz de TIVIT y Daniel Zamora IPS para realizar el proceso de habilitacion de suscripcion de servicios PaaS Azure DevOps requeridos por IPS.
B17: 45750 | D17: Jorge Quiroz - TIVIT Daniel Zamora - IPS | E17: Cesar Gonzalez | F17: REQ | G17: Call Cuenta y Suscripcion Servicios PaaS Azure DevOps | H17: Call semanal en donde se revisan temas pendientes y proyectos en curso correspondientes a Cloud Services IPS.
B18: 45750 | D18: Operaciones IPS | E18: Cesar Gonzalez | F18: REQ | G18: Call Seguimiento: [IPS] Temas Pendientes - Cloud Services ☁ | H18: Se coordina actividad para realizar fuera de horario correspondiente al proceso de remediacion de vulnerabilidades detectadas en instancias AWS/Azure por nuestra area de Ciberseguridad. Para esta actividad se realizara la remediacion de 4 instancias Azure y 2 instancias AWS.
B19: 45750 | D19: Operaciones IPS | E19: Cesar Gonzalez | F19: REQ | G19: Fuera De Horario - Actividad de Remediación de Vulnerabilidades | H19: Se gestiona call con usuario Ricardo Orellana debido a problemas con usuarios con rol dbamanager creados en recursos Azure SQL
B20: 45750 | D20: Ricardo Orellana DBA IPS | E20: Cesar Gonzalez | F20: REQ | G20: Call Revision Acceso Azure SQL | H20: Se gestiona call para revisar problemas con servicios Weblogics, debido a una actualizacion realizad ay reportada por nuestra area de Ciberseguridad IPS, el cual se realiza actualizacion del servicio PrimeFaces a version 11
B21: 45751 | D21: Equipo Middleware IPS | E21: Cesar Gonzalez | F21: REQ | G21: Call Validacion De Servicios WLSPROD03-WLSPROD04 | H21: Se gestiona call correspondiente a la planificacion y coordinacion de trabajos para las actividades de cambio de hora.
B22: 45751 | D22: Operaciones IPS | E22: Cesar Gonzalez | F22: REQ | G22: Call Planificacion Cambio De Hora - Invierno 2025 | H22: Se gestiona actividad planificada fuera de horario, en conjunto con area Servicios Oracle IPS para realizar mantenicon y reparacion de isntancia WebLogic WLSProd03 ya que presento problemas en su actualizacion de repositoris Pramefaces solcitado como mitigacion por el area de Ciberseguridad.
B23: 45754 | D23: Servicios Oracle IPS | E23: Cesar Gonzalez | F23: REQ | G23: Actividad Planificada - Fuera De Horario: Apoyo Mantencion y Configuracion Instancia Weblogic - WLSPROD03 AWS | H23: Call semanal en donde se revisan temas pendientes y proyectos en curso correspondientes a Cloud Services IPS.
B24: 45755 | D24: Operaciones IPS | E24: Cesar Gonzalez | F24: REQ | G24: Call Seguimiento: [IPS] Temas Pendientes - Cloud Services ☁ | H24: Se procede con la eliminacion de Snapshots obtenidos en el proceso de mitigacion de vulnerabilidades ya resueltos en los sistemas de Azure.
B25: 45756 | D25: Operaciones IPS | E25: Cesar Gonzalez | F25: REQ | G25: AZ IPS - Eliminar RG Snapshots Remediacion | H25: Se realiza call con DBA Ricardo Orellana para explicar la situacion del proyecto AlwaysOn SQLent y detalles del proceso de migracion del servicio de LB que actualmente utiliza, ya que MS Azure descontinuara los servicios de LB Classic el 30/09/25
... B36: 45764 | D36: Area Ciberseguridad IPS Operaciones IPS | E36: Cesar Gonzalez | F36: REQ | G36: Call Revision FW AWS/Azure | H36: Se coordina call para definir las estrategias de implementacion de FW PAN en los servicios Cloud actuales que contiene IPS.
B37: 45765 | D37: FERIADO | E37: Cesar Gonzalez | F37: REQ | G37: Feriado
B38: 45768 | D38: Area Operaciones CHA-IPS Morris Opazo | E38: Cesar Gonzalez | F38: REQ | G38: Call CHA - Modernizacion a AWS | H38: Se realiza call para revisar procesos de modernizacion de apps por obselecencia actual en CHA e IPS
B39: 45769 | D39: Area Ciberseguridad IPS | E39: Cesar Gonzalez | F39: REQ | G39: Ticket N° 14684 - Hallazgos ANCI - ipsenlinea | H39: Se genera ticket debido a los hallazgos de seguridad obtenidos para el servicio persona.ipsenlinea.cl
B40: 45770 | D40: IPS - TIVIT - CHA - AWS | E40: Cesar Gonzalez | F40: REQ | G40: [EXTERNO]RV: IPS / AWS / Tivit Kickoff Proyecto Fase 2-Implementación de Landing Zone, Adecuación de Cuentas AWS y Epicas de Seguridad | H40: Se cita a kick off migración LZ de IPS - Reunion en oficinas de IPS
B41: 45770 | D41: IPS | E41: Cesar Gonzalez | F41: REQ | G41: FinOps Azure IPS | H41: Reunion para revisar estrategias FinOps en ambiente Azure.
B42: 45770 | D42: Gonzalo Sepulveda IPS | E42: Cesar Gonzalez | F42: REQ | G42: Ticket N° 14707 - Apagado PDP QA | H42: Solicitud de encendido de ambientes PDP QA para la fecha indicada
B43: 45771 | D43: Palo Alto Ciberseguridad IPS Operaciones IPS | E43: Cesar Gonzalez | F43: REQ | G43: Call Implmentacion FW PAN - Cuentas AWS IPS | H43: Call para verificar las formas de implementacion de FW PAN en cuentas AWS IPS
B44: 45775 | D44: TIVIT - Operaciones IPS | E44: Cesar Gonzalez | F44: REQ | G44: Call Implementacion y planificacion - Puesta en Marcha Azure DevOps | H44: Call para revisar y planificar la puesta en marcha y estrategia del servicio Azure DevOps para IPS
B45: 45775 | D45: Sergio Santibañez | E45: Cesar Gonzalez | F45: REQ | G45: Ticket N° 14735 - Encendidos Instancias AFPER UAT | H45: Ticket para realizar el encendido de ambientes UAT AFPER
B46: 45775 | D46: Operaciones IPS | E46: Cesar Gonzalez | F46: REQ | G46: Call Seguimiento: [IPS] Temas Pendientes - Cloud Services ☁ | H46: Call semanal en donde se revisan temas pendientes y proyectos en curso correspondientes a Cloud Services IPS.
B47: 45775 | D47: Gonzalo Sepulveda IPS | E47: Cesar Gonzalez | F47: REQ | G47: Ticket N° 14752 - Apagados DEV PDP | H47: Ticket para no realizar el apagado de isntancias PDP DEV durante esta fecha.
B48: 45777 | D48: TIVIT - Operaciones IPS | E48: Cesar Gonzalez | F48: REQ | G48: Call IPS: revision Ticket R95489 | H48: Call de revision de ticket
B49: 45777 | D49: Area Operaciones y NOC IPS | E49: Cesar Gonzalez | F49: REQ | G49: Call Monitoreo - Coordinación Programación Encendido/Apagado Instancias | H49: Call de revision correspondiente al procedimiento de encendidos y apagados de instancias solcitados y reportar al NOC correspondiente.
B50: 45779 | C50: 45778 | D50: Ciberseguridad Operaciones IPS | E50: Cesar Gonzalez | F50: REQ | G50: Ticket N°: 14776 - Evento De Seguridad | H50: Se gestiona ticket por parte de nuestra area de Ciberseguridad por eventos de seguridad detectados en AWS.
...

Sheet RodrigoLorca
B1: FECHA SOLICITUD | C1: Periodo | D1: AREA / PERSONAL SOLICITANTE | E1: PROFESIONAL | F1: INC / REQ / WARNING | G1: Actividad | H1: Detalle / Observación | I1: Estado (en proceso, pendiente, finalizado) | J1: Tiempo estimado actividad
B2: 45726 | C2: 45717 | D2: Fernando Lopez - IPS | E2: Rodrigo Lorca | F2: REQ | G2: Transferencia datos criticos entre entidades | H2: Transferencia de archivos criticos archivo fallecidos
B3: 45726 | D3: Ingenieria y Servicios - IPS | E3: Rodrigo Lorca | F3: REQ | G3: Actividades de Administración Plataformas Tecnologicas IPS | H3: Actividades de administración y mantenimiento de los sistemas core de IPS administrados por el área de ingenieria y servicios IPS, destacando coreagil, reforma agil, legados avbmenu, FTPs y SFTPs core IPS, reforma concesión, pisee, SSSonline, asignacion familiar, contacto ips, garantia estatal, reloj virtual, gobierno transparente, mora presunta, entre otros.
B4: 45726 | D4: Jose Luis Hernandez | E4: Rodrigo Lorca | F4: INC | G4: Analisis de Falla masiva en consultas WS Reg Civil | H4: Pruebas y analisis por fallas complejas que afectan a institución en consumo de WS pisee.
B5: 45727 | D5: Jose Luis Hernandez | E5: Rodrigo Lorca | F5: INC | G5: Analisis de Falla masiva en consultas WS Reg Civil | H5: Se hace un analisis detallado del problema presentado en la consulta de WS que consumen la entidad registro civil, se encuentra que el problema era el sobreconsumo por parte de IPS, dado una actividad que estaban realizando desde cliente de negocio desde sucursal santo domingo. Se envia un correo de alerta y aviso por su detención.
B6: 45727 | D6: Carlos Salamanca - IPS | E6: Rodrigo Lorca | F6: REQ | G6: Pasos a producción de sistemas bajo administración | H6: Revisión de documentacion FINS para pasos a producción. R1732 STI - 145466 - 102
B7: 45728 | D7: Sandra Gomez - IPS | E7: Rodrigo Lorca | F7: REQ | G7: Transferencia datos criticos entre entidades | H7: Archivos de consulta BPH para el SRCeI proceso marzo 2025
B8: 45728 | D8: Williams Franco - IPS | E8: Rodrigo Lorca | F8: REQ | G8: Revisión reforma agil | H8: Se realiza revisión y aclaración por problema lenvatado por cliente, generado por utilizar un nodo en especifico y no el DNS balanceado
B9: 45729 | D9: Ingenieria y Servicios - IPS | E9: Rodrigo Lorca | F9: REQ | G9: Actividades de Administración Plataformas Tecnologicas IPS | H9: Actividades de administración y mantenimiento de los sistemas core de IPS administrados por el área de ingenieria y servicios IPS, destacando coreagil, reforma agil, legados avbmenu, FTPs y SFTPs core IPS, reforma concesión, pisee, SSSonline, asignacion familiar, contacto ips, garantia estatal, reloj virtual, gobierno transparente, mora presunta, entre otros.
B10: 45730 | D10: Jose Luis Hernandez | E10: Rodrigo Lorca | F10: INC | G10: Falla Sistema AF | H10: Se realizan acciones de revisión y levantamiento de servicio asignacion familiar que se vio afectado
B11: 45730 | D11: Ingenieria y Servicios - IPS | E11: Rodrigo Lorca | F11: INC | G11: Error avbmenu | H11: Resolución de incidente en AVBmenu
B12: 45730 | D12: Jorge Ahumada - IPS | E12: Rodrigo Lorca | F12: REQ | G12: Modificación servicio programado | H12: Se realiza cambio de configuración horarios de subida y bajada de avbmenu debido a actividad extraordinaria
B13: 45733 | D13: Ingenieria y Servicios - IPS | E13: Rodrigo Lorca | F13: REQ | G13: Actividades de Administración Plataformas Tecnologicas IPS | H13: Actividades de administración y mantenimiento de los sistemas core de IPS administrados por el área de ingenieria y servicios IPS, destacando coreagil, reforma agil, legados avbmenu, FTPs y SFTPs core IPS, reforma concesión, pisee, SSSonline, asignacion familiar, contacto ips, garantia estatal, reloj virtual, gobierno transparente, mora presunta, entre otros.
B14: 45733 | D14: Operaciones - IPS | E14: Rodrigo Lorca | F14: REQ | G14: Gestión de instalación FINS ambientes administrados | H14: Instalación de variadas fichas en ambientes de desarrollo y QA para distintos proyectos que se encuentran llevando a cabo en IPS.
... B52: 45756 | D52: Operaciones - IPS | E52: Rodrigo Lorca | F52: REQ | G52: Gestión de instalación FINS ambientes administrados | H52: Instalación de variadas fichas en ambientes de desarrollo y QA para distintos proyectos que se encuentran llevando a cabo en IPS.
B53: 45757 | C53: 45748 | D53: Ingenieria y Servicios - IPS | E53: Rodrigo Lorca | F53: INC | G53: Falla WebServices Pisee IPS | H53: Analisis y pruebas por falla alertada al momento de consumir los WS desde plataforma Pisee. Se solicita a personal de santo domingo, que puedan proceder a finalizar sus ejecuciones, ya que, se encontraban saturando las consultas y las TPS que la entidad de registro civil tiene permitidas para el instituto.
B54: 45757 | D54: Claudia Flores - IPS | E54: Rodrigo Lorca | F54: INC | G54: Falla y lentitud CoreAgil | H54: Se trabaja en conjunto con soportes de desarrollo, dado los problemas que alertan desde un área de negocio sto domingo, el soporte no encuentra fallas de oepraciones interna y es informado a cliente final.
B55: 45757 | D55: Carlos Salamanca - IPS | E55: Rodrigo Lorca | F55: REQ | G55: Pasos a producción de sistemas bajo administración | H55: Revisión de documentacion FINS para pasos a producción
B56: 45758 | D56: Operaciones - IPS | E56: Rodrigo Lorca | F56: REQ | G56: Gestión de instalación FINS ambientes administrados | H56: Instalación de variadas fichas en ambientes de desarrollo y QA para distintos proyectos que se encuentran llevando a cabo en IPS.
B57: 45761 | D57: Claudia Flores - IPS | E57: Rodrigo Lorca | F57: INC | G57: Falla y lentitud CoreAgil | H57: Se trabaja en conjunto con soportes de desarrollo, dado los problemas que alertan desde un área de negocio sto domingo, el soporte no encuentra fallas de oepraciones interna y es informado a cliente final.
B58: 45761 | D58: Claudia Flores - MAFIPS | E58: Rodrigo Lorca | F58: INC | G58: Error avbmenu | H58: Resolución de incidente en AVBmenu
B59: 45762 | D59: Operaciones - IPS | E59: Rodrigo Lorca | F59: REQ | G59: Gestión de instalación FINS ambientes administrados | H59: Instalación de variadas fichas en ambientes de desarrollo y QA para distintos proyectos que se encuentran llevando a cabo en IPS.
B60: 45763 | D60: Jose Luis Hernandez - IPS | E60: Rodrigo Lorca | F60: REQ | G60: Transferencia datos criticos entre entidades | H60: Transferencia de archivo critico entre IPS y SRCeI
B61: 45763 | D61: Claudia Flores - MAFIPS | E61: Rodrigo Lorca | F61: INC | G61: Error avbmenu | H61: Resolución de incidente en AVBmenu
B62: 45763 | D62: Operaciones - IPS | E62: Rodrigo Lorca | F62: REQ | G62: Gestión de instalación FINS ambientes administrados | H62: Instalación de variadas fichas en ambientes de desarrollo y QA para distintos proyectos que se encuentran llevando a cabo en IPS.
B63: 45764 | D63: Patricio Sotomayor - IPS | E63: Rodrigo Lorca | F63: REQ | G63: Transferencia datos criticos entre entidades | H63: Transferencia de archivo critico entre IPS y SRCeI
B64: 45764 | D64: Ingenieria y Servicios - IPS | E64: Rodrigo Lorca | F64: REQ | G64: Actividades de Administración Plataformas Tecnologicas IPS | H64: Actividades de administración y mantenimiento de los sistemas core de IPS administrados por el área de ingenieria y servicios IPS, destacando coreagil, reforma agil, legados avbmenu, FTPs y SFTPs core IPS, reforma concesión, pisee, SSSonline, asignacion familiar, contacto ips, garantia estatal, reloj virtual, gobierno transparente, mora presunta, entre otros.
B65: 45768 | D65: Fernando Lopez - IPS | E65: Rodrigo Lorca | F65: REQ | G65: Transferencia datos criticos entre entidades | H65: Transferencia de archivos criticos archivo fallecidos
... B98: 45786 | D98: Alejandra Luna - IPS | E98: Rodrigo Lorca | F98: REQ | G98: Reinicio nodo core agil | H98: Se realiza reinicio de servicio nodo core agil
B99: 45787 | C99: 45778 | D99: NOC - Abenis & Patricio Soyomayor - IPS | E99: Rodrigo Lorca | F99: INC | G99: Incidente AF | H99: Se realiza levantamiento de servicio productivo caido asociado a asignación familiar
B100: 45787 | D100: IPS | E100: Rodrigo Lorca | F100: REQ | G100: Proceso CDP Mensual | H100: Se modifican parametros y validación de servicios legados avbmenu por excepción de proceso horario Autraliano.
B101: 45788 | D101: IPS | E101: Rodrigo Lorca | F101: REQ | G101: Proceso CDP Mensual | H101: Se modifican parametros y validación de servicios legados avbmenu por excepción de proceso horario Autraliano.
B102: 45789 | D102: Victor Muñoz - IPS | E102: Rodrigo Lorca | F102: REQ | G102: Transferencia datos criticos entre entidades | H102: Transferencia de archivos criticos archivo fallecidos
B103: 45789 | D103: Ingenieria y Servicios - IPS | E103: Rodrigo Lorca | F103: REQ | G103: Actividades de Administración Plataformas Tecnologicas IPS | H103: Actividades de administración y mantenimiento de los sistemas core de IPS administrados por el área de ingenieria y servicios IPS, destacando coreagil, reforma agil, legados avbmenu, FTPs y SFTPs core IPS, reforma concesión, pisee, SSSonline, asignacion familiar, contacto ips, garantia estatal, reloj virtual, gobierno transparente, mora presunta, entre otros.
B104: 45789 | D104: Ingenieria y Servicios - IPS | E104: Rodrigo Lorca | F104: INC | G104: Errores Inesperados Core Agil | H104: Se realiza analisis y posterior solución a problemas de errores inesperados presentados en core agil
B105: 45790 | D105: Operaciones - IPS | E105: Rodrigo Lorca | F105: REQ | G105: Gestión de instalación FINS ambientes administrados | H105: Instalación de variadas fichas en ambientes de desarrollo y QA para distintos proyectos que se encuentran llevando a cabo en IPS.
B106: 45791 | D106: Ingenieria y Servicios - IPS | E106: Rodrigo Lorca | F106: REQ | G106: Actividades de Administración Plataformas Tecnologicas IPS | H106: Actividades de administración y mantenimiento de los sistemas core de IPS administrados por el área de ingenieria y servicios IPS, destacando coreagil, reforma agil, legados avbmenu, FTPs y SFTPs core IPS, reforma concesión, pisee, SSSonline, asignacion familiar, contacto ips, garantia estatal, reloj virtual, gobierno transparente, mora presunta, entre otros.
B107: 45792 | D107: Williams Franco - MAFIPS | E107: Rodrigo Lorca | F107: INC | G107: Error avbmenu | H107: Se valida problema de lentitud en servicio avbmenu, sin encontrar problema reportado u otro. Se le pide a mafips que analicen directamente la sucursal o equipos de usuarios finales.
B108: 45793 | D108: Ingenieria y Servicios - IPS | E108: Rodrigo Lorca | F108: REQ | G108: Reforma QA y problemas de lentitud | H108: Se realizan variadas pruebas con personal de soporte de desarrollo, y se encuentra en horario AM que habian realizado una copia mal desde producción a la DB de QA. Luego de esto, sigue el problema de lentitud, y se pide la deshabilitación de politicas desde servidor de aplicación QA para descartar problemas de FW.
B109: 45793 | D109: Operaciones - IPS | E109: Rodrigo Lorca | F109: REQ | G109: Gestión de instalación FINS ambientes administrados | H109: Instalación de variadas fichas en ambientes de desarrollo y QA para distintos proyectos que se encuentran llevando a cabo en IPS.
...

Sheet PabloSalazar
B1: FECHA SOLICITUD | C1: Periodo | D1: AREA / PERSONAL SOLICITANTE | E1: PROFESIONAL | F1: INC / REQ / WARNING | G1: Actividad | H1: Detalle / Observación | I1: Estado (en proceso, pendiente, finalizado) | J1: Tiempo estimado actividad
B2: 45748 | C2: 45748 | D2: Gonzalo Sepulveda | E2: Pablo Salazar | F2: REQ | G2: 10.150.234.185 ayuda con accesos
B3: 45749 | C3: 45749 | D3: Gonzalo Sepulveda | E3: Pablo Salazar | F3: REQ | G3: 10.150.234.185 ayuda con accesos
B4: 45750 | C4: 45750 | D4: Area de segurida informatica | E4: Pablo Salazar | F4: REQ | G4: hallazgo Primeface y java
B5: 45751 | C5: 45751 | D5: Area de segurida informatica | E5: Pablo Salazar | F5: INC | G5: hallazgo Primeface y java
B6: 45754 | C6: 45752 | D6: Area de segurida informatica | E6: Pablo Salazar | F6: REQ | G6: hallazgo Primeface y java
B7: 45755 | C7: 45753 | D7: Oscar Luis Mora Araya | E7: Pablo Salazar | F7: REQ | G7: OHSProd01.ips.gob.cl revision
B8: 45756 | C8: 45754 | D8: Iann Isaias Sandoval Gonzalez | E8: Pablo Salazar | F8: REQ | G8: Aranda 14562, accesos a servidores
B9: 45757 | C9: 45755 | D9: Iann Isaias Sandoval Gonzalez | E9: Pablo Salazar | F9: REQ | G9: Aranda 14562, accesos a servidores
B10: 45758 | C10: 45756 | D10: Francis Ostos | E10: Pablo Salazar | F10: REQ | G10: acceosos a RelojVirtual y srv-relojcontrol
B11: 45761 | C11: 45757 | D11: Francis Ostos | E11: Pablo Salazar | F11: REQ | G11: acceosos a RelojVirtual y srv-relojcontrol
B12: 45762 | C12: 45758 | D12: Paola Lillo | E12: Pablo Salazar | F12: REQ | G12: cuenta de alejandro Ipinza en los linux
B13: 45763 | C13: 45759 | D13: Paola Lillo | E13: Pablo Salazar | F13: REQ | G13: cuenta de alejandro Ipinza en los linux
... B226: 46066 | C226: 46064 | D226: mesa de ayuda | E226: Pablo Salazar | F226: REQ | G226: espacio en server pirihuico
B227: 46069 | C227: 46065 | E227: Pablo Salazar | G227: vacaciones
B228: 46070 | C228: 46066 | E228: Pablo Salazar | G228: vacaciones
B229: 46071 | C229: 46067 | E229: Pablo Salazar | G229: vacaciones
B230: 46072 | C230: 46068 | E230: Pablo Salazar | G230: vacaciones
B231: 46073 | C231: 46069 | E231: Pablo Salazar | G231: vacaciones
B232: 46076 | C232: 46070 | E232: Pablo Salazar | G232: vacaciones
B233: 46077 | C233: 46071 | E233: Pablo Salazar | G233: vacaciones
B234: 46078 | C234: 46072 | E234: Pablo Salazar | G234: vacaciones
B235: 46079 | C235: 46073 | E235: Pablo Salazar | G235: vacaciones
B236: 46080 | C236: 46074 | E236: Pablo Salazar | G236: vacaciones
B237: 46083 | C237: 46083 | D237: mesa de ayuda | E237: Pablo Salazar | F237: REQ | G237: -ALERTAS DE DISCO servidor AWS -Asistencia alerta espacio en disco servidor AWS - Wlsprod03 IP 10.200.2.253
B238: 46084 | C238: 46084 | D238: mesa de ayuda | E238: Pablo Salazar | F238: REQ | G238: -alertas AZS4HANAPRD01 IP 10.88.1.135
B239: 46085 | C239: 46085 | D239: mesa de ayuda | E239: Pablo Salazar | F239: REQ | G239: -alertas AZS4HANAPRD01 IP 10.88.1.136
B240: 46086 | C240: 46086 | D240: mesa de ayuda /infraestructura | E240: Pablo Salazar | F240: REQ | G240: -aranda 17330 -agente en unas maquinas de AWS
B241: 46087 | C241: 46087 | D241: infraestructura | E241: Pablo Salazar | F241: REQ | G241: trabajos aws key fjilbertof
B242: 46090 | C242: 46088 | D242: infraestructura | E242: Pablo Salazar | F242: REQ | G242: capacidad de discos server aws ipv6 en el SOLMAN
B243: 46091 | C243: 46089 | D243: infraestructura | E243: Pablo Salazar | F243: REQ | G243: capacidad de discos server aws ipv6 en el SOLMAN
B244: 46092 | C244: 46090 | D244: infraestructura | E244: Pablo Salazar | F244: REQ | G244: capacidad de discos server aws | H244: Se trabaja en planilla envida por Daniel Zamora para saber la capacidad de disco de una granja en una granja de server | I244: 3h | J244: finalizado
B245: 46093 | C245: 46091 | D245: infraestructura | E245: Pablo Salazar | F245: REQ | G245: capacidad de discos server aws | H245: Se trabaja en planilla envida por Daniel Zamora para saber la capacidad de disco de una granja en una granja de server | I245: 2h | J245: finalizado
B246: 46094 | C246: 46092 | D246: infraestructura | E246: Pablo Salazar | F246: REQ | G246: capacidad de discos server aws | H246: Se trabaja en planilla envida por Daniel Zamora para saber la capacidad de disco de una granja en una granja de server | I246: 3h | J246: finalizado
B247: 46097 | C247: 46093 | D247: infraestructura | E247: Pablo Salazar | F247: REQ | G247: key maquinas aws | H247: Se trabaja en maquinas de aws en el orden de sus .pem y .pub. Anotando en planillas para su facilidad al acceder. | I247: 2h | J247: finalizado
B248: 46098 | C248: 46094 | D248: infraestructura | E248: Pablo Salazar | F248: REQ | G248: key maquinas aws / trabajos en planilla de maquinas virtules | H248: Se trabaja en maquinas de aws en el orden de sus .pem y .pub. Anotando en planillas para su facilidad al acceder. / Se mantiene el orden de infraestructura de cada maquina administrada, cpu,discos, ram,etc. | I248: 3h | J248: finalizado
B249: 46099 | C249: 46095 | D249: infraestructura | E249: Pablo Salazar | F249: REQ | G249: key maquinas aws / trabajos en planilla de maquinas virtules | H249: Se trabaja en maquinas de aws en el orden de sus .pem y .pub. Anotando en planillas para su facilidad al acceder. / Se mantiene el orden de infraestructura de cada maquina administrada, cpu,discos, ram,etc. | I249: 3h | J249: finalizado
B250: 46100 | C250: 46096 | D250: infraestructura | E250: Pablo Salazar | F250: REQ | G250: trabajos en planilla de maquinas virtules | H250: Se mantiene el orden de infraestructura de cada maquina administrada, cpu,discos, ram,etc. | I250: 2h | J250: finalizado
B251: 46101 | C251: 46097 | D251: infraestructura | E251: Pablo Salazar | F251: REQ | G251: trabajos en planilla de maquinas virtules | H251: Se mantiene el orden de infraestructura de cada maquina administrada, cpu,discos, ram,etc. | I251: 2h | J251: finalizado
B252: 46104 | C252: 46098 | D252: infraestructura | E252: Pablo Salazar | F252: REQ | G252: revision aranda ticket | H252: se revisa aranda para saver si ahi requeriineto nuevos, y lo antiguos para poder avanzar en ellos. | I252: 30 min | J252: finalizado
...

Sheet GonzaloRodriguez
B1: FECHA SOLICITUD | C1: Periodo | D1: AREA / PERSONAL SOLICITANTE | E1: PROFESIONAL | F1: INC / REQ / WARNING | G1: Actividad | H1: Detalle / Observación | I1: Estado (en proceso, pendiente, finalizado) | J1: Tiempo estimado actividad
B2: 45726 | C2: 45717 | D2: Paola Lillo | E2: Gonzalo Rodriguez | F2: REQ | G2: Migración a Discos Administrados MV Azure | H2: Realizar migracion de discos administrado en MV apagadas (Robot)
B3: 45737 | C3: 45717 | D3: Paola Lillo | E3: Gonzalo Rodriguez | F3: REQ | G3: Migración a Discos Administrados MV Azure | H3: Realizar migracion de discos administrado en MV apagadas (Robot)
B4: 45740 | C4: 45717 | D4: Paola Lillo | E4: Gonzalo Rodriguez | F4: REQ | G4: Documentación de vpn Azure y AWS | H4: Generar documentación entre las vpn de Azure y AWS
B5: 45741 | C5: 45717 | D5: Paola Lillo | E5: Gonzalo Rodriguez | F5: REQ | G5: Documentación de Firewall Palo Alto | H5: Generar documentación de FW Palo Alto Azure
B6: 45741 | C6: 45717 | D6: Pamela Nogues | E6: Gonzalo Rodriguez | F6: REQ | G6: Redireccion de tráfico hacia internet por Firewall Palo Alto Azure | H6: Configuración de FW y creación de las tablas de rutas para subredes de Desarrollo
B7: 45741 | C7: 45717 | D7: Ricardo Briones | E7: Gonzalo Rodriguez | F7: REQ | G7: Ticket 14376 - Permisos App Service | H7: Se otorgan permisos Website Contributor a usuario Christian Fuentes para apps Hpfront-prd y Hpback-prd
B8: 45742 | C8: 45717 | D8: Gonzalo Sepulveda | E8: Gonzalo Rodriguez | F8: REQ | G8: Ticket 14386 - Apagado Maquinas Virtuales AWS | H8: Se deshabilita apaga automatico instancias PDP UAT
B9: 45743 | C9: 45717 | D9: Gonzalo Sepulveda | E9: Gonzalo Rodriguez | F9: REQ | G9: Ticket 14399 - Apagado Maquinas Virtuales AWS | H9: Se deshabilita apaga automatico instancias PDP UAT
B10: 45744 | C10: 45717 | D10: Pamela Nogues | E10: Gonzalo Rodriguez | F10: REQ | G10: Levantamiento MV produccion Azure | H10: Se entrega detalle de todas las MV de producción
B11: 45748 | C11: 45748 | D11: Gonzalo Sepulveda | E11: Gonzalo Rodriguez | F11: REQ | G11: Ticket 14456 - Apagado Maquinas Virtuales AWS | H11: Se deshabilita apaga automatico instancias PDP UAT
B12: 45749 | C12: 45748 | D12: Pamela Nogues | E12: Gonzalo Rodriguez | F12: REQ | G12: Levantamiento Subnets produccion Azure | H12: Se entrega detalle de todas las Subnets de producción
B13: 45750 | C13: 45748 | D13: Daniel Zamora + TIVIT | E13: Gonzalo Rodriguez | F13: REQ | G13: Azure Devops | H13: Se crea nueva suscripcion en cuenta IPS-CHILE-AE e implementación de herramienta Azure Devops
... B17: 45762 | C17: 45748 | D17: Daniel Zamora | E17: Gonzalo Rodriguez | F17: REQ | G17: Azure Devops | H17: Reunion con Chile Atiende sobre experiencia e Implementacion de Azure Devops
B18: 17/04/2025 | C18: 46113 | D18: Gonzalo Sepúlveda | E18: Gonzalo Rodriguez | F18: REQ | G18: Deshablitar autoapagado | H18: no realizar el apagado de las máquinas de PDP del ambiente SIT
B19: 21/04/2025 | C19: 46478 | D19: Gonzalo Sepúlveda | E19: Gonzalo Rodriguez | F19: REQ | G19: Deshablitar autoapagado | H19: no realizar el apagado del ambiente de DEV de PDP
B20: 22/04/2025 | C20: 46844 | D20: Carlos Leins | E20: Gonzalo Rodriguez | F20: REQ | G20: Firewall PAN | H20: Preparacion para integracion de firewall PAN en ambiente productivo
B21: 23/04/2025 | C21: 47209 | D21: Gonzalo Sepúlveda | E21: Gonzalo Rodriguez | F21: REQ | G21: Deshablitar autoapagado | H21: deshabilitación del apagado de la máquina de SIT del ambiente de PDP
B22: 24/04/2025 | C22: 47574 | D22: Jorge Echenique | E22: Gonzalo Rodriguez | F22: REQ | G22: Revsion app service | H22: revisión de appservices tramites digitales ambiente QA para validar funcionamiento de servicios instalados.
B23: 45772 | C23: 47939 | D23: Sergio Santibañez | E23: Gonzalo Rodriguez | F23: REQ | G23: Encendido de MV | H23: Se solicita subir maquinas UAT de AFPER uat-afper-consulta.ips.gob.cl, uat-afper-consulta-2.ips.gob.cl, uat-afper-reclamo.ips.gob.cl
B24: 45775 | C24: 48305 | D24: Patricio Pizarro | E24: Gonzalo Rodriguez | F24: INC | G24: Alerta por intentos de inyección SQL a través de tráfico HTTP | H24: Los intentos provinieron de las IPs 10.88.7.4 y 10.88.7.8, utilizando distintos puertos de origen hacia IP 10.151.2.35
B25: 45779 | C25: 48670 | D25: Gabriel Nunez | E25: Gonzalo Rodriguez | F25: REQ | G25: Encendido de MV | H25: mantener encendidos ambientes sit y dev del portal de pago
B26: 45782 | C26: 45778 | D26: Pamela Nogues | E26: Gonzalo Rodriguez | F26: REQ | G26: Configuración Palo Alto Firewall PAN HA | H26: Definiciones
B27: 45790 | C27: 45778 | D27: Team AWS | E27: Gonzalo Rodriguez | F27: REQ | G27: AWS Landing Zone Fase 2 | H27: Inicio Fase II, parte 1
B28: 45790 | C28: 45778 | D28: Team AWS | E28: Gonzalo Rodriguez | F28: REQ | G28: AWS Landing Zone Fase 2 | H28: Inicio Fase II, parte 2
B29: 45791 | C29: 45778 | D29: Gonzalo Sepulveda | E29: Gonzalo Rodriguez | F29: REQ | G29: Apagado Automático EC2 | H29: Deshabilitar Apagado automático Ambiente SIT Portal de Pago
B30: 45793 | C30: 45778 | D30: Team AWS | E30: Gonzalo Rodriguez | F30: REQ | G30: Configuración Palo Alto Firewall PAN HA | H30: Avances de configuración
B31: 45796 | C31: 45778 | D31: Team AWS | E31: Gonzalo Rodriguez | F31: REQ | G31: AWS Landing Zone Fase 2 | H31: Sesion de Levantamiento
B32: 45796 | C32: 45778 | D32: Carlos Villanueva | E32: Gonzalo Rodriguez | F32: REQ | G32: Revision App service Azure | H32: Troubleshooting app service cnormativo-be
B33: 45797 | C33: 45778 | D33: Team AWS | E33: Gonzalo Rodriguez | F33: REQ | G33: AWS Landing Zone Fase 2 | H33: Sesion de Levantamiento
B34: 45799 | C34: 45778 | D34: Luz Rivera | E34: Gonzalo Rodriguez | F34: REQ | G34: Revision performance app service | H34: Reinicio y escalamiento horizontal de plan ASEWIN02 para proceso en sdm-back
... B295: 46091 | C295: 46082 | D295: Jorge Echeñique | E295: Gonzalo Rodriguez | F295: REQ | G295: Pruebas Api Gateways cuenta SrvTransversales | H295: Ejecución de pruebas Api Gateway Pisee Notificador
B296: 46092 | C296: 46082 | D296: Fabian Flores | E296: Gonzalo Rodriguez | F296: REQ | G296: Habilitacion de permisos en Storage Account | H296: Habilitacion de permisos Reader en Storage Account: almacenexpedienteafdev a ffloresl.srv@ips.gob.cl | I296: Finalizado | J296: 1 hr
B297: 46092 | C297: 46082 | D297: Jorge Echeñique | E297: Gonzalo Rodriguez | F297: REQ | G297: Pruebas Api Gateways cuenta SrvTransversales | H297: Ejecución de pruebas Api Gateway Pisee Notificador | I297: Finalizado | J297: 4 hr
B298: 46093 | C298: 46082 | D298: Jorge Echeñique - Marco | E298: Gonzalo Rodriguez | F298: REQ | G298: Api Gateways cuenta SrvTransversales | H298: Correccion de la Ejecución de pruebas Api Gateway Pisee Notificador | I298: Finalizado | J298: 3 hr
B299: 46093 | C299: 46082 | D299: Andres Bastias | E299: Gonzalo Rodriguez | F299: REQ | G299: Azure App service pensionfem | H299: Resivión de Informe Ciberseguridad Hacking Etico App service Pensionfem | I299: Finalizado | J299: 3 hr
B300: 46094 | C300: 46082 | D300: Paola Lillo | E300: Gonzalo Rodriguez | F300: REQ | G300: Azure App service pensionfem | H300: Se evalua solución para exponer api desde Azure api manager | I300: Finalizado | J300: 1 hr
B301: 46096 | C301: 46082 | D301: Daniel Zamora | E301: Gonzalo Rodriguez | F301: REQ | G301: Actualización minisitio aportefamiliar.cl | H301: Se actualiza codigo fuente a repositorio gitlab en ramas qa y prod | I301: Finalizado | J301: 2 hr
B302: 46097 | C302: 46082 | D302: Andres Bastias | E302: Gonzalo Rodriguez | F302: REQ | G302: Azure App service pensionfem | H302: Se evalua solución para exponer api desde Azure api manager | I302: Finalizado | J302: 2 hr
B303: 46098 | C303: 46082 | D303: Mauricio Miranda | E303: Gonzalo Rodriguez | F303: REQ | G303: Azure Reglas Network Security Group | H303: Se solicita regla para denegar servicios desde NSG de subnet tanzu a base de datos sql (tanzu-mgmt-cluster-node-nsg) solo puerto 443 | I303: Finalizado | J303: 1 hr
...

Sheet OscarMora
B1: FECHA SOLICITUD | C1: Periodo | D1: AREA / PERSONAL SOLICITANTE | E1: PROFESIONAL | F1: INC / REQ / WARNING | G1: Actividad | H1: Detalle / Observación | I1: Estado (en proceso, pendiente, finalizado) | J1: Tiempo estimado actividad | K1: HH EE
B2: 45747 | C2: =IF(B2<>"",B2,"") -> 45747 | D2: Gonzalo Sepulveda | E2: Oscar Mora | F2: REQ | G2: Revisión en linea de logs por falla en una función del aplicativo
B3: 45749 | C3: 45748 | D3: Gonzalo Sepulveda | E3: Oscar Mora | F3: REQ | G3: Revisión de SR por falla en subida de algunos archivos
B4: 45750 | C4: 45748 | D4: Gonzalo Sepulveda | E4: Oscar Mora | F4: REQ | G4: Reinicio de nodos y agente de ODI
B5: 45751 | C5: 45748 | D5: IPS en Linea | E5: Oscar Mora | F5: INC | G5: Falla en IPS en linea: Post aplicación de parchado de seguridad | H5: Se restaura un FS por parte de AWS, se reinician plataformas y hay problema con osbprod01 para iniciar sistema
B6: 45754 | C6: 45748 | D6: IPS en Linea | E6: Oscar Mora | F6: REQ | G6: Mantenimiento Programado - Servicio WebLogic - Lunes 07 de Abril - 18:00 Hrs | H6: Se realiza en el servidor 10.150.150.103 | K6: 2
B7: 45755 | C7: 45748 | D7: PFP | E7: Oscar Mora | F7: INC | G7: Problema con app | H7: Fallo en nodo 1 y 2
B8: 45755 | C8: 45748 | D8: Jorge Eheñique | E8: Oscar Mora | F8: INC | G8: problema en un servicio que consume el ohs, desde ayer en la tarde esta abajo, el mismo servicio de siempre; http://ohsprod01.ips.gob.cl:7777/CLAT/HP/v1_0/HistoricoPrevisional?wsdl | H8: Maquina no respondía por ssh, se escala con Infra para su apoyo. Infra revisa y faltaba un check (de 2) en inicio. Se procede a reiniciar la maquina (AWS - Sao Pablo) - Demoró en iniciar pero quedó arriba
B9: 45755 | C9: 45748 | D9: Portal de Pago | E9: Oscar Mora | F9: REQ | G9: Reunión con Oracle por problema de certificado en OHS | H9: Reunión de trabajo
B10: 45757 | C10: 45748 | D10: Portal de Pago | E10: Oscar Mora | F10: REQ | G10: Iteración con Oracle por SR SR 3-40360525901 | H10: Problem in the OHS which when loading a file of any size between 2 to 700 MB which gives us a connect
B11: 45758 | C11: 45748 | D11: Portal de Pago | E11: Oscar Mora | F11: REQ | G11: Reunión con Oracle por problema de certificado en OHS | H11: Reunión de trabajo
B12: 45758 | C12: 45748 | D12: Portal de Pago | E12: Oscar Mora | F12: REQ | G12: Iteración con Oracle por SR SR 3-40360525901 | H12: Problem in the OHS which when loading a file of any size between 2 to 700 MB which gives us a connect
B13: 45762 | C13: 45748 | D13: PFP | E13: Oscar Mora | F13: INC | G13: Sistema PFP no funciona | H13: Nodos: 1 y 3 con falla. Se realiza reinicio sanitario controlado, recuperando la plataforma
B14: 45762 | C14: 45748 | D14: Portal de Pago | E14: Oscar Mora | F14: REQ | G14: Reunión de entrega PDP
B15: 45762 | C15: 45748 | D15: PFP | E15: Oscar Mora | F15: REQ | G15: Reunion Informativa PFP y Otros | H15: a razón de las multiples fallas de pfp en estas 2 semanas
B16: 45762 | C16: 45748 | D16: Portal de Pago | E16: Oscar Mora | F16: REQ | G16: Iteración con Oracle por SR SR 3-40360525901 | H16: Problem in the OHS which when loading a file of any size between 2 to 700 MB which gives us a connect
B17: 45763 | C17: 45748 | D17: Portal de Pago | E17: Oscar Mora | F17: REQ | G17: Instalación properties en PRD | H17: Ejecución según lo indicado en el documento FINS - Ticket 14634
B18: 45768 | C18: 45748 | D18: PFP | E18: Oscar Mora | F18: INC | G18: Sistema PFP no funciona | H18: Servidor con problemas de espacio en el /u01, por lo que no funcionaba nodos 1 y 3
B19: 45768 | C19: 45748 | D19: Portal de Pago | E19: Oscar Mora | F19: REQ | G19: Iteración con Oracle por SR SR 3-40360525901 | H19: Problem in the OHS which when loading a file of any size between 2 to 700 MB which gives us a connect
B20: 45768 | C20: 45748 | D20: Gonzalo Sepulveda | E20: Oscar Mora | F20: REQ | G20: Configuración https en OHS DEV | H20: Se reconfiguran archivos de sistema OHS para que tomaran
B21: 45768 | C21: 45748 | D21: Gonzalo Sepulveda | E21: Oscar Mora | F21: INC | G21: No se puede conectar al portal de pago de DEV | H21: Problema con su equipo, el cual no tenia acceso por reglas de FW
B22: 45768 | C22: 45748 | D22: Gonzalo Sepulveda | E22: Oscar Mora | F22: REQ | G22: Portal de Pago PROD: Se suben archivos a procesar | H22: Falla nuevamente por OHS, se capturan videos para subir al SR con Oracle por issue
B23: 45768 | C23: 45748 | D23: Portal de Pago | E23: Oscar Mora | F23: REQ | G23: Iteración con Oracle por SR SR 3-40360525901 | H23: Se itera SR, respondiendo lo consultado y se suben videos de lo realizado en falla de subida de archivos en PdP PROD
B24: 45769 | C24: 45748 | D24: Gonzalo Sepulveda | E24: Oscar Mora | F24: REQ | G24: OHS DEV creación de usuario para Claudio Oyarzun | H24: Usuario existía, solo se resetea la pass y se realizan pruebas de acceso y ejecución de procesos en plataforma
B25: 45770 | C25: 45748 | D25: PFP | E25: Oscar Mora | F25: INC | G25: Sistema PFP no funciona | H25: Nodo 1 con problemas, se reinicia y se recupera el sistema.
B26: 45771 | C26: 45748 | D26: PFP | E26: Oscar Mora | F26: INC | G26: Sistema PFP no funciona | H26: Nodo 1 con problemas, se reinicia y se recupera el sistema.
... B33: 45776 | C33: 45748 | D33: ASIMU | E33: Oscar Mora | F33: INC | G33: No se puede accedes al sistema ASIMU | H33: Se reinicia los nodos del wls y queda operativo
B34: 45777 | C34: 45748 | D34: ASIMU | E34: Oscar Mora | F34: INC | G34: Falla en Solicitud Asignación por Muerte/Cuota Mortuoria - Empresas | H34: Antes de presentar problemas Informix, falla en lentitud de despliegue | K34: todo el día
B35: 45777 | C35: 45748 | D35: AFPER | E35: Oscar Mora | F35: REQ | G35: Paso a producción AFPER Urgente | H35: ticket 14780
B36: 45778 | C36: 45778 | D36: ASIMU | E36: Oscar Mora | F36: INC | G36: Sigue falla en Solicitud Asignación por Muerte/Cuota Mortuoria - Empresas | H36: El problema estaba en url ssl a papperless (Sergio Santibañez) el 30 de abril de la suceso dieron de baja una url http://siagf.paperless.cl, debian cambiar los desarrollos a http://ws.pias.suseso.cl/ eso le pega a facilita. van a mandar un comunicado informando que el problema se mantendrá el lunes mientras trabajan en la solución | K36: todo el día
B37: 45782 | C37: 45778 | D37: Gonzalo Sepulveda | E37: Oscar Mora | F37: REQ | G37: Ticket 14792: reiniciar los nodos de ODI PRD e iniciar el plan de carga | H37: se realiza lo solicitado
B38: 45782 | C38: 45778 | D38: Gonzalo Sepulveda | E38: Oscar Mora | F38: INC | G38: Problemas con el procesamiento de planes de carga | H38: Era solo lentitud en BD, por la alta carga
B39: 45782 | C39: 45778 | D39: Victor Caroca | E39: Oscar Mora | F39: REQ | G39: Ayuda con datos de unos datasource de bpel. Son estos dos: eis/DB/Facilita_Afper y eis/DB/Facilita_Informix | H39: se realiza lo solicitado
B40: 45782 | C40: 45778 | D40: Victor Caroca | E40: Oscar Mora | F40: REQ | G40: buscar el datasource Facilita_CoreAgil, en productivo
B41: 45782 | C41: 45778 | D41: Victor Caroca | E41: Oscar Mora | F41: REQ | G41: Solicitud de configuraciones de la carpeta IPS_HOME\appl
B42: 45783 | C42: 45778 | D42: Priscilla Valenzuela | E42: Oscar Mora | F42: INC | G42: Reunión configuraciones, revision logs, realizar pruebas | H42: Todo el día en encontrar solución con el área de ChileAtiende
B43: 45784 | C43: 45778 | D43: Priscilla Valenzuela | E43: Oscar Mora | F43: INC | G43: Reunión configuraciones, revision logs, realizar pruebas | H43: La solución se implementor parte de la gente de desarrollo del área de ChileAtiende.
B44: 45786 | C44: 45778 | D44: Daniel Zamora | E44: Oscar Mora | F44: INC | G44: Problemas en osb afper | H44: estaba pegado y la consola de admin no respondía
B45: 45786 | C45: 45778 | D45: Daniel Zamora | E45: Oscar Mora | F45: INC | G45: Falla en servicio del BUS AFPProject, por problemas en respuesta | H45: Arrojaba en los logs socket timeout en servicio AFPProject, ya que estaba direccionando http://siagf.paperless.cl, y debe ser ahora a pias.suceso.cl. Problema solucionado con paso a prod de nuevo componente. Quedó con errores pero operativo. Daniel Zamora enviará correo con detalles y compromiso de eliminar los logs. | K45: todo el día
B46: 45803 | C46: 45778 | D46: Priscilla Valenzuela | E46: Oscar Mora | F46: REQ | G46: Reunión: Estrategia bajada ipsenlinea
...

Sheet GabrielNuñez
B1: FECHA SOLICITUD | C1: Periodo | D1: AREA / PERSONAL SOLICITANTE | E1: PROFESIONAL | F1: INC / REQ / WARNING | G1: Actividad | H1: Detalle / Observación | I1: Estado (en proceso, pendiente, finalizado) | J1: Tiempo estimado actividad
B2: 45726 | C2: 09:00 - 18:00 | D2: Operaciones | E2: Jose Luis Hernandez | F2: REQ | G2: Gestión y prueba de accesos
B3: 45727 | C3: 09:00 - 18:00 | D3: Operaciones | E3: Jose Luis Hernandez | F3: REQ | G3: Gestión y prueba de accesos
B4: 45728 | C4: 09:00 - 18:00 | D4: Operaciones | E4: Jose Luis Hernandez | F4: REQ | G4: Gestión y prueba de accesos
B5: 45729 | C5: 09:00 - 18:00 | D5: Operaciones | E5: Patricio Ramirez | F5: INC | G5: Reunión sobre caídas del servidor BD
B6: 45730 | C6: 09:00 - 18:00 | D6: DYM | E6: Jorge León | F6: INC | G6: Revisión de repositorios ODI
B7: 45733 | C7: 09:00 - 18:00 | D7: DYM | E7: Jorge León | F7: INC | G7: Revisión de repositorios ODI
B8: 45734 | C8: 09:00 - 18:00 | D8: DYM | E8: Jorge León | F8: INC | G8: Revisión de repositorios ODI
B9: 45735 | C9: 09:00 - 18:00 | D9: DYM | E9: Jorge León | F9: INC | G9: Revisión de repositorios ODI
B10: 45736 | C10: 09:00 - 18:00 | D10: DYM | E10: Jorge León | F10: INC | G10: Revisión de repositorios ODI
B11: 45737 | C11: 09:00 - 18:00 | D11: DYM | E11: Jorge León | F11: INC | G11: Planificación migración repositorios
B12: 45740 | C12: 09:00 - 18:00 | D12: DYM | E12: Jorge León | F12: INC | G12: Revisión de requisitos para migrar repositorios
B13: 45741 | C13: 09:00 - 18:00 | D13: DYM | E13: Jorge León | F13: INC | G13: Revisión de requisitos para migrar repositorios
... B195: 46000 | C195: 09:00 - 18:00 | D195: INFRAESTRUCTURA | E195: PAOLA LILLO | F195: REQ | G195: PROYECTO LANDING ZONE, AFPER
B196: 46001 | C196: 09:00 - 18:00 | D196: DYM | E196: JORGE LEÓN | F196: INC | G196: INCIDENCIAS ODI ELEGIBILIDAD | H196: Se realiza informe respectivo
B197: 46002 | C197: 09:00 - 18:00 | D197: DYM | E197: JORGE LEÓN | F197: Alerta | G197: REVISIÓN ODI, STAGING PRODUCCIÓN | H197: Es un seguimiento al incidente del día anterior
B198: 46003 | C198: 09:00 - 18:00 | D198: INGENIERIA | E198: PATRICIO RAMIREZ | F198: REQ | G198: MEJORAS SERVIDOR ODI
B199: 46006 | C199: 09:00 - 18:00 | D199: INGENIERIA | E199: PATRICIO RAMIREZ | F199: REQ | G199: MEJORAS SERVIDOR ODI
B200: 46007 | C200: 09:00 - 18:00 | D200: INGENIERIA | E200: PATRICIO RAMIREZ | F200: REQ | G200: MEJORAS SERVIDOR ODI
B201: 46008 | C201: 09:00 - 18:00 | D201: INGENIERIA | E201: PATRICIO RAMIREZ | F201: REQ | G201: MEJORAS SERVIDOR ODI
B202: 46009 | C202: 09:00 - 18:00 | D202: INGENIERIA | E202: PATRICIO RAMIREZ | F202: REQ | G202: MEJORAS SERVIDOR ODI
B203: 46010 | C203: 09:00 - 18:00 | D203: INGENIERIA | E203: PATRICIO RAMIREZ | F203: REQ | G203: MEJORAS SERVIDOR ODI
B204: 46013 | C204: 09:00 - 18:00 | D204: INGENIERIA | E204: PATRICIO RAMIREZ | F204: REQ | G204: MEJORAS SERVIDOR ODI
B205: 46014 | C205: 09:00 - 18:00 | D205: INGENIERIA | E205: PATRICIO RAMIREZ | F205: REQ | G205: MEJORAS SERVIDOR ODI
B206: 46015 | C206: 09:00 - 18:00 | D206: INGENIERIA | E206: PATRICIO RAMIREZ | F206: REQ | G206: MEJORAS SERVIDOR ODI
B207: 46017 | C207: 09:00 - 18:00 | D207: DYM | E207: CHRISTIAN ROJAS | F207: INC | G207: ERROR ODI PRODUCCIÓN, MEMORY HEAP, REINICIO | H207: Se realiza informe repectivo
B208: 46020 | C208: 09:00 - 18:00 | D208: DYM | E208: CHRISTIAN ROJAS | F208: INC | G208: MEJORAS EN LOS PARAMETROS DE ODI EN CLIENTES | H208: Es un seguimiento al incidente del día anterior
B209: 46021 | C209: 09:00 - 18:00 | D209: DYM | E209: CHRISTIAN ROJAS | F209: INC | G209: REVISIÓN DE ESTADO DE LAS EJECUCIONES ODI PRODUCCIÓN | H209: Es un seguimiento al incidente del día anterior
B210: 46022 | C210: 09:00 - 18:00 | D210: INGENIERIA | E210: PATRICIO RAMIREZ | F210: REQ | G210: MEJORAS SERVIDOR ODI
B211: 46024 | C211: 09:00 - 18:00 | D211: DYM | E211: CHRISTIAN ROJAS | F211: INC | G211: MONITOREO MODULO APS Y DMPAGOS | H211: Se reportaba lentitud, pero no se observó nada
B212: 46027 | C212: 09:00 - 18:00 | D212: INGENIERIA | E212: PATRICIO RAMIREZ | F212: REQ | G212: MEJORAS SERVIDOR ODI
B213: 46028 | C213: 09:00 - 18:00 | D213: INGENIERIA | E213: PATRICIO RAMIREZ | F213: REQ | G213: MEJORAS SERVIDOR ODI
B214: 46029 | C214: 09:00 - 18:00 | D214: INGENIERIA | E214: PATRICIO RAMIREZ | F214: REQ | G214: MEJORAS SERVIDOR ODI
B215: 46030 | C215: 09:00 - 18:00 | D215: INGENIERIA | E215: PATRICIO RAMIREZ | F215: REQ | G215: MEJORAS SERVIDOR ODI
B216: 46031 | C216: 09:00 - 18:00 | D216: DYM | E216: CHRISTIAN ROJAS | F216: INC | G216: ERROR ENVIO DE CORREO MÓDULO DMPAGOS | H216: Se presenta informe respectivo.
B217: 46034 | C217: 09:00 - 18:00 | D217: DYM | E217: CHRISTIAN ROJAS | F217: INC | G217: MONITOREO ENVÍO DE CORREOS ODI PRD | H217: Se valida que el cambio realizado no afectó otros módulos. Es un seguimiento al incidente del día anterior.
B218: 46035 | C218: 09:00 - 18:00 | D218: INGENIERIA | E218: PATRICIO RAMIREZ | F218: REQ | G218: MEJORAS SERVIDOR ODI ONPREMISE
B219: 46036 | C219: 09:00 - 18:00 | D219: INGENIERIA | E219: PATRICIO RAMIREZ | F219: REQ | G219: MEJORAS SERVIDOR ODI ONPREMISE
B220: 46037 | C220: 09:00 - 18:00 | D220: DYM | E220: Paola Bustamante | F220: REQ | G220: Soporte pdp subida de archivos | H220: Se valida el funcionamiento y los logs, se detecta que la casilla de correo está full y hay usuarios que no tienen permisos
B221: 46038 | C221: 09:00 - 18:00 | D221: DYM | E221: Paola Bustamante | F221: REQ | G221: Soporte pdp subida de archivos | H221: Se valida el funcionamiento y los logs, se detecta que la casilla de correo está full y hay usuarios que no tienen permisos
...

Sheet AmericoSaravia
B1: FECHA SOLICITUD | C1: Periodo | D1: AREA / PERSONAL SOLICITANTE | E1: PROFESIONAL | F1: INC / REQ / WARNING | G1: Actividad | H1: Detalle / Observación | I1: Estado (en proceso, pendiente, finalizado) | J1: Tiempo estimado actividad | K1: Ticket
B2: 45719 | C2: 09:00 - 18:59 | D2: Melinka Chacon | E2: Asaravia | F2: REQ | G2: Revisión SGI. Se encontro que problemas venia desde informix. Por lo cual se escalo a Jose Luis | I2: FINALIZADO | J2: 30 min
B3: 45720 | C3: 09:00 - 18:59 | D3: Gonzalo Sepulveda | E3: Gonzalo Sepulveda | F3: REQ | G3: Revisión de configuraciones SSL | I3: FINALIZADO
B4: 45720 | C4: 18:00 - 21:00 | D4: Gonzalo Sepulveda | E4: Gonzalo Sepulveda | F4: REQ | G4: Revisión y pruebas SSL UAT-SIT-DEV | I4: FINALIZADO
B5: 45720 | C5: 09:00 - 18:59 | D5: Jorge Leon | E5: Jorge Leon | F5: REQ | G5: Revisión ODI por proceso pegado, se revisa plataforma encontrando errores de java.lang.OutOfMemoryError, por lo cual se realiza tunning JVM | I5: FINALIZADO
B6: 45720 | C6: 09:00 - 18:59 | D6: Nicolas Patricio Reyes Escalona | E6: Nicolas Patricio Reyes Escalona | F6: REQ | G6: Revisión sistemas de SGI | I6: FINALIZADO
B7: 45722 | C7: 09:00 - 18:59 | D7: Fernanda Yañez | E7: Fernanda Yañez | F7: REQ | G7: revisióbn caida calculo PFP, se realiza reinicio de servicios owsm server | I7: FINALIZADO | K7: ticket # 886 - Sistema PFP Caído // 1440
B8: 45722 | C8: 09:00 - 18:59 | D8: Paola Lillo | E8: Paola Lillo | F8: REQ | G8: Revisión pueto 9001 de server proosb, se realiza reinicio de servicios de osb. | I8: FINALIZADO
B9: 45722 | C9: 09:00 - 18:59 | D9: Jesus Antonio Chavez Bastias | E9: Jesus Antonio Chavez Bastias | F9: REQ | G9: Webservices Alertados - OSBPROD01 | I9: FINALIZADO
B10: 45722 | C10: 09:00 - 18:59 | D10: Jorge Leon | E10: Jorge Leon | F10: REQ | G10: Solicitud revisión de conexiones ODI | I10: FINALIZADO
B11: 45726 | C11: 09:00 - 18:59 | D11: Gema Molina | E11: Gema Molina | F11: REQ | G11: Prueba de conectividad a nivel nacional Teams | I11: FINALIZADO
B12: 45727 | C12: 09:00 - 18:59 | D12: Carlos Salamaca | E12: Carlos Salamaca | F12: REQ | G12: Status Paso a operaciones Portal de Pago | I12: FINALIZADO
B13: 45728 | C13: 09:00 - 18:59 | D13: Paola Lillo | E13: Paola Lillo | F13: REQ | G13: Revisión servidores de QA | I13: FINALIZADO
B14: 45729 | C14: 09:00 - 18:59 | D14: Cristian Villanueva | E14: Cristian Villanueva | F14: REQ | G14: Refvisión ODI y Sistema AF | I14: FINALIZADO
B15: 45729 | C15: 09:00 - 18:59 | D15: Jorge Leon | E15: Jorge Leon | F15: REQ | G15: Solicitud creación ODISYN_ODI_REPO | I15: FINALIZADO
B16: 45730 | C16: 09:00 - 18:59 | D16: Fernanda Yañez | E16: Fernanda Yañez | F16: REQ | G16: Estimados, nos reportan nuevamente que sistema PFP no responde. http://sistemacalculopfp.ips.gob.cl:9001/PFP/login.xhtml | I16: FINALIZADO | K16: ticket # 1444 - Sistema PFP Caído
B17: 45733 | C17: 09:00 - 18:59 | D17: Mauricio Miranda | E17: Mauricio Miranda | F17: REQ | G17: Revisión espacios /u01 de server proosb02, Alertas! Sensor Disk Free: /u01 MV proosb02 IP 10.150.150.104 | I17: FINALIZADO
B18: 45368 | C18: 09:00 - 18:59 | D18: Patricio Ramirez | E18: Patricio Ramirez | F18: REQ | G18: FW: IPS: Revisión caso 3-39559650149 Problemas con OHS después de configurar SSL | I18: FINALIZADO
B19: 45370 | C19: 09:00 - 18:59 | D19: Patricio Ramirez | E19: Patricio Ramirez | F19: REQ | G19: Status Paso a operaciones Portal de Pago. | I19: FINALIZADO
B20: 45370 | C20: 09:00 - 18:59 | D20: Jesuis Chavex | E20: Jesuis Chavex | F20: REQ | G20: Revisar proosb01 no tiene corriendo los procesos httpd.worker? | I20: FINALIZADO
B21: 45737 | C21: 09:00 - 18:59 | D21: Jonathan Nñez | E21: Jonathan Nñez | F21: REQ | G21: Alerta puertos VM Proosb01 (10.150.150.103) PM 20-03 puertos 9001 | I21: FINALIZADO
B22: 45737 | C22: 09:00 - 18:59 | D22: Fernanda Yañez | E22: Fernanda Yañez | F22: REQ | G22: Estimados, nos reportan nuevamente que sistema PFP no responde. http://sistemacalculopfp.ips.gob.cl:9001/PFP/login.xhtml | I22: FINALIZADO | K22: ticket # 1450 - Sistema PFP Caído
B23: 45737 | C23: 09:00 - 18:59 | D23: Patricio Ramirez | E23: Patricio Ramirez | F23: REQ | G23: Status SR 3-39559650149 oracle - SSL - Weblogic | I23: FINALIZADO
B24: 45738 | C24: 09:00 - 18:59 | D24: Patricio Ramirez | E24: Patricio Ramirez | F24: REQ | G24: Se comparten evidencias del caso de SSL oracle | I24: FINALIZADO
B25: 45741 | C25: 09:00 - 18:59 | D25: Williams Franco | E25: Williams Franco | F25: REQ | G25: Estimados, nos reportan nuevamente que sistema PFP no responde. http://sistemacalculopfp.ips.gob.cl:9001/PFP/login.xhtml | I25: FINALIZADO | K25: ticket # 1454 - Sistema PFP Caído
